# app/core/security.py
from datetime import datetime, timedelta
from typing import Optional
from jose import JWTError, jwt
from passlib.context import CryptContext
from fastapi import Depends, HTTPException, status
from fastapi.security import OAuth2PasswordBearer
from sqlalchemy.ext.asyncio import AsyncSession
from sqlalchemy.future import select
from app.core.config import settings
from app.core.database import get_db
from app.models.user import User

# Password hashing
pwd_context = CryptContext(schemes=["bcrypt"], deprecated="auto")

# OAuth2 scheme
oauth2_scheme = OAuth2PasswordBearer(tokenUrl="/auth/login")

def verify_password(plain_password: str, hashed_password: str) -> bool:
    return pwd_context.verify(plain_password, hashed_password)

def get_password_hash(password: str) -> str:
    return pwd_context.hash(password)

def create_access_token(data: dict, expires_delta: Optional[timedelta] = None) -> str:
    to_encode = data.copy()
    if expires_delta:
        expire = datetime.utcnow() + expires_delta
    else:
        expire = datetime.utcnow() + timedelta(minutes=settings.ACCESS_TOKEN_EXPIRE_MINUTES)
    to_encode.update({"exp": expire})
    return jwt.encode(to_encode, settings.SECRET_KEY, algorithm=settings.ALGORITHM)

async def get_current_user(
    token: str = Depends(oauth2_scheme),
    db: AsyncSession = Depends(get_db)
) -> User:
    credentials_exception = HTTPException(
        status_code=status.HTTP_401_UNAUTHORIZED,
        detail="Could not validate credentials",
        headers={"WWW-Authenticate": "Bearer"},
    )
    try:
        payload = jwt.decode(
            token, 
            settings.SECRET_KEY, 
            algorithms=[settings.ALGORITHM]
        )
        username: str = payload.get("sub")
        if username is None:
            raise credentials_exception
    except JWTError:
        raise credentials_exception

    query = select(User).where(User.username == username)
    result = await db.execute(query)
    user = result.scalar_one_or_none()
    
    if user is None:
        raise credentials_exception
    return user